<?xml version="1.0"?>
<robot name="igvc24_bot">
  
  <link name="base_link">
    <visual>
      <origin rpy="0 -0 3.14" xyz="-0.35 0 0"/>
      <geometry>
        <mesh filename="file:///home/kallrax/abhiyaan_ws_ros2/igvc24_ws/src/igvc_sim/meshes/igvc24/igvc_bot.dae" scale="0.001 0.001 0.001"/>
      </geometry>
    </visual>

    <collision>
      <origin rpy="0 -0 3.14" xyz="-0.35 0 0"/>
      <geometry>
        <mesh filename="file:///home/kallrax/abhiyaan_ws_ros2/igvc24_ws/src/igvc_sim/meshes/igvc24/igvc_bot.dae" scale="0.001 0.001 0.001"/>
      </geometry>   
    </collision>

    <inertial>
      <mass value="10"/>
      <inertia ixx="0.166667" ixy="0.0" ixz="0.0" iyy="0.166667" iyz="0.0" izz="0.166667"/>
    </inertial>
  </link>
    
  <link name = "perpendicular">
    <visual>
      <origin rpy="0 0 0" xyz="0 0 0"/>
      <geometry>
        <box size="0.0001 0.00001 0.00001"/>
      </geometry>
    </visual>
        
    <collision>
      <origin rpy="0 0 0" xyz="0 0 0"/>
      <geometry>
        <box size="0.0001 0.00001 0.00001"/>
      </geometry>
    </collision>
        
    <inertial>
      <mass value="0"/>
      <inertia ixx="0.0" ixy="0.0" ixz="0.0" iyy="0.0" iyz="0.0" izz="0.0"/>
    </inertial>
  </link>

  <link name="zed_camera">
    <visual>
      <origin rpy="0 0 1.5707" xyz="-0.015 -0.005 0"/>
      <geometry>
        <mesh filename="file:///home/kallrax/abhiyaan_ws_ros2/igvc24_ws/src/igvc_sim/meshes/igvc24/zed2i.dae" scale="1 1 1"/>
      </geometry>
    </visual>  

    <collision>
      <origin rpy="0 0 1.5707" xyz="-0.015 -0.005 0"/>
      <geometry>
        <mesh filename="file:///home/kallrax/abhiyaan_ws_ros2/igvc24_ws/src/igvc_sim/meshes/igvc24/zed2i.dae"/>
      </geometry>
    </collision>
      
    <inertial>
      <mass value="0.5"/>
      <inertia ixx="0.166667" ixy="0.0" ixz="0.0" iyy="0.166667" iyz="0.0" izz="0.166667"/>
    </inertial>
  </link>

  <gazebo reference="zed_camera">
    <sensor name="zedcam" type="depth">
      <always_on>true</always_on>
      <update_rate>15</update_rate>
      <pose>0 0 0 0 0 0</pose>
      <camera name="zed_depth_camera">
        <horizontal_fov>1.46608</horizontal_fov>
        <image>
          <width>1920</width>
          <height>1080</height>
          <format>B8G8R8</format>
        </image>
        <clip>
          <near>0.05</near>
          <far>8</far>
        </clip>
      </camera>
            
      <plugin name="depthcam_driver" filename="libgazebo_ros_camera.so">
        <ros>
          <namespace>depthcam</namespace>
          <!-- <remapping>${name}/points:=depth/points</remapping> -->
        </ros>
        <camera_name>zed2i</camera_name>
        <frame_name>perpendicular</frame_name>
        <hack_baseline>0.07</hack_baseline>
        <min_depth>0.05</min_depth>
        <max_depth>8.0</max_depth>
      </plugin>
    </sensor>
  </gazebo>

  <link name="wheel1">
    <visual>
      <geometry>
        <mesh filename="file:///home/kallrax/abhiyaan_ws_ros2/igvc24_ws/src/igvc_sim/meshes/igvc24/igvc_wheel.dae" scale="0.001 0.001 0.001"/>
      </geometry>
      <origin rpy ="0 0 0" xyz="0 0 0"/>
    </visual>

    <collision>
      <geometry>
        <cylinder radius="0.12" length="0.04"/>
      </geometry>
      <origin rpy ="1.5707 0 1.5707" xyz="-0.065 0 0"/>
    </collision>

    <inertial>
      <mass value="5"/>
      <inertia ixx="0.166667" ixy="0.0" ixz="0.0" iyy="0.166667" iyz="0.0" izz="0.166667"/>
    </inertial>
  </link>

  <link name="wheel2">
    <visual>
      <geometry>
        <mesh filename="file:///home/kallrax/abhiyaan_ws_ros2/igvc24_ws/src/igvc_sim/meshes/igvc24/igvc_wheel.dae" scale="0.001 0.001 0.001"/>
      </geometry>
    <origin rpy ="0 0 0" xyz="0 0 0"/>
    </visual>

    <collision>
      <geometry>
        <cylinder radius="0.12" length="0.04"/>
      </geometry>
      <origin rpy ="1.5707 0 1.5707" xyz="-0.065 0 0"/>
    </collision>

    <inertial>
      <mass value="5"/>
      <inertia ixx="0.166667" ixy="0.0" ixz="0.0" iyy="0.166667" iyz="0.0" izz="0.166667"/>
    </inertial>
  </link>

  <link name="castor_ball">
    <visual>
      <geometry>
        <sphere radius="0.05"/>
      </geometry>
      <origin rpy="0 0 0" xyz="0 0 0"/>
    </visual>

    <collision>
      <geometry>
        <sphere radius="0.05"/>
      </geometry>
      <origin rpy="0 0 0" xyz="0 0 0"/>
    </collision>

    <inertial>
      <mass value="3"/>
      <inertia ixx="0.166667" ixy="0.0" ixz="0.0" iyy="0.166667" iyz="0.0" izz="0.166667"/>
    </inertial>
  </link>

  <link name="castor_cylinder">
    <visual>
      <geometry>
        <cylinder length="0.03" radius="0.05"/>
      </geometry>
      <origin rpy="0 0 0" xyz="0 0 0"/>
    </visual>

    <collision>
      <geometry>
        <cylinder length="0.03" radius="0.05"/>
      </geometry>
      <origin rpy ="0 0 0" xyz="0 0 0"/>
    </collision>
      
    <inertial>
      <mass value="2"/>
      <inertia ixx="0.166667" ixy="0.0" ixz="0.0" iyy="0.166667" iyz="0.0" izz="0.166667"/>
    </inertial>
  </link>

  <link name="castor_ball2">
    <visual>
      <geometry>
        <sphere radius="0.05"/>
      </geometry>
      <origin rpy="0 0 0" xyz="0 0 0"/>
    </visual>
    
    <collision>
      <geometry>
        <sphere radius="0.05"/>
      </geometry>
      <origin rpy="0 0 0" xyz="0 0 0"/>
    </collision>
    
    <inertial>
      <mass value="3"/>
      <inertia ixx="0.166667" ixy="0.0" ixz="0.0" iyy="0.166667" iyz="0.0" izz="0.166667"/>
    </inertial>
  </link>
      
  <link name="castor_cylinder2">
    <visual>
      <geometry>
        <cylinder length="0.03" radius="0.05"/>
      </geometry>
      <origin rpy="0 0 0" xyz="0 0 0"/>
    </visual>
    
    <collision>
      <geometry>
        <cylinder length="0.03" radius="0.05"/>
      </geometry>
      <origin rpy ="0 0 0" xyz="0 0 0"/>
    </collision>
        
    <inertial>
      <mass value="2"/>
      <inertia ixx="0.166667" ixy="0.0" ixz="0.0" iyy="0.166667" iyz="0.0" izz="0.166667"/>
    </inertial>
  </link>
  
  <joint name="body_to_wheel1" type="continuous">
    <parent link="base_link"/>
    <child link="wheel1"/>
    <axis xyz="1 0 0"/>
    <origin rpy ="0 0 3.14" xyz="0.2 0.0 0"/>
  </joint>
  
  <joint name="body_to_wheel2" type="continuous">
    <parent link="base_link"/>
    <child link="wheel2"/>
    <axis xyz="-1 0 0"/>
    <origin rpy ="0 0 0" xyz="-0.22 0.0 0"/>
  </joint>

  <joint name="body_to_castor_cylinder" type="continuous">
    <parent link="base_link"/>
    <child link="castor_cylinder"/>
    <axis xyz="0 0 1"/>
    <origin rpy ="0 0 0" xyz="0.002746 -0.377785 -0.01"/>
  </joint>

  <joint name="cylinder_to_castor_ball" type="continuous">
    <parent link="castor_cylinder"/>
    <child link="castor_ball"/>
    <axis xyz="0 1 0"/>
    <origin rpy ="0 0.132544 0" xyz="0 0 -0.065"/>
  </joint>

  <joint name="camera_to_body" type="fixed">
    <parent link="base_link"/>
    <child link="zed_camera"/>
    <origin rpy ="0 0 1.5707" xyz="-0.02 0.13 0.905"/>
  </joint>

  <joint name="body_to_castor_cylinder2" type="continuous">
    <parent link="base_link"/>
    <child link="castor_cylinder2"/>
    <axis xyz="0 0 1"/>
    <origin rpy ="0 0 0" xyz="0.002746 0.377785 0"/>
  </joint>

  <joint name="cylinder_to_castor_ball2" type="continuous">
    <parent link="castor_cylinder2"/>
    <child link="castor_ball2"/>
    <axis xyz="0 1 0"/>
    <origin rpy ="0 0.132544 0" xyz="0 0 -0.065"/>
  </joint>
  
  <joint name="perp" type="fixed">
    <parent link="base_link"/>
    <child link="perpendicular"/>
    <origin rpy ="-1.5707 0 -1.5707" xyz="-0.02 0.13 0.905"/>
  </joint>

  <gazebo>
    <plugin filename="libgazebo_ros_diff_drive.so" name="differential_drive_controller">
      <ros>
        <namespace>/igvc24_bot</namespace>
      </ros>

      <!-- wheels -->
      <left_joint>body_to_wheel2</left_joint>
      <right_joint>body_to_wheel1</right_joint>

      <!-- kinematics -->
      <wheel_separation>0.67336</wheel_separation>
      <wheel_diameter>0.4</wheel_diameter>

      <!-- limits -->
      <max_wheel_torque>100</max_wheel_torque>
      <max_wheel_acceleration>1.0</max_wheel_acceleration>

      <!-- output -->
      <publish_odom>true</publish_odom>
      <publish_odom_tf>true</publish_odom_tf>

      <odometry_frame>odom</odometry_frame>
      <robot_base_frame>base_link</robot_base_frame>
    </plugin>
  </gazebo>

  <!-- COLORS -->

  <gazebo reference="base_link"> 
    <material>Gazebo/BlueLaser</material>
  </gazebo>

  <gazebo reference="zed_camera"> 
    <material>Gazebo/Grey</material>
  </gazebo>

  <gazebo reference="wheel1"> 
    <material>Gazebo/Black</material>
  </gazebo>

  <gazebo reference="wheel2"> 
    <material>Gazebo/Black</material>
  </gazebo>

  <gazebo reference="castor_cylinder"> 
    <material>Gazebo/Black</material>
  </gazebo>

  <gazebo reference="castor_cylinder2"> 
    <material>Gazebo/Black</material>
  </gazebo>

  <gazebo reference="castor_ball"> 
    <material>Gazebo/Black</material>
  </gazebo>

  <gazebo reference="castor_ball2"> 
    <material>Gazebo/Black</material>
  </gazebo>
</robot>